Traceback (most recent call last):
  File "/Users/cghiaus/opt/anaconda3/lib/python3.9/site-packages/jupyter_cache/executors/utils.py", line 58, in single_nb_execution
    executenb(
  File "/Users/cghiaus/opt/anaconda3/lib/python3.9/site-packages/nbclient/client.py", line 1112, in execute
    return NotebookClient(nb=nb, resources=resources, km=km, **kwargs).execute()
  File "/Users/cghiaus/opt/anaconda3/lib/python3.9/site-packages/nbclient/util.py", line 74, in wrapped
    return just_run(coro(*args, **kwargs))
  File "/Users/cghiaus/opt/anaconda3/lib/python3.9/site-packages/nbclient/util.py", line 53, in just_run
    return loop.run_until_complete(coro)
  File "/Users/cghiaus/opt/anaconda3/lib/python3.9/asyncio/base_events.py", line 642, in run_until_complete
    return future.result()
  File "/Users/cghiaus/opt/anaconda3/lib/python3.9/site-packages/nbclient/client.py", line 553, in async_execute
    await self.async_execute_cell(
  File "/Users/cghiaus/opt/anaconda3/lib/python3.9/site-packages/nbclient/client.py", line 857, in async_execute_cell
    self._check_raise_for_error(cell, exec_reply)
  File "/Users/cghiaus/opt/anaconda3/lib/python3.9/site-packages/nbclient/client.py", line 760, in _check_raise_for_error
    raise CellExecutionError.from_cell_and_msg(cell, exec_reply_content)
nbclient.exceptions.CellExecutionError: An error occurred while executing the following cell:
------------------
t = dt * np.arange(data.shape[0])   # time vector

fig, axs = plt.subplots(2, 1)
# plot outdoor and indoor temperature
axs[0].plot(t / 3600 / 24, data['To'], label='$Î¸_{outdoor}$')
axs[0].plot(t / 3600 / 24, y_exp.val, label='$Î¸_{indoor}$')
axs[0].set(ylabel='Temperatures, $Î¸$ / Â°C',
           title='Simulation for weather')
axs[0].legend(loc='upper right')

# plot total solar radiation and HVAC heat flow
axs[1].plot(t / 3600 / 24, data['Î¦tot'], label='$Î¦_{total}$')
axs[1].plot(t / 3600 / 24, q_HVAC, label='$q_{HVAC}$')
axs[1].set(xlabel='Time, $t$ / day',
           ylabel='Heat flows, $q$ / W')
axs[1].legend(loc='upper right')

fig.tight_layout()
------------------

[0;31m---------------------------------------------------------------------------[0m
[0;31mAttributeError[0m                            Traceback (most recent call last)
[0;32m/var/folders/vp/k617ngs97xq4vlzlj5ts6sch0000gn/T/ipykernel_9584/3030888392.py[0m in [0;36m<module>[0;34m[0m
[1;32m      4[0m [0;31m# plot outdoor and indoor temperature[0m[0;34m[0m[0;34m[0m[0m
[1;32m      5[0m [0maxs[0m[0;34m[[0m[0;36m0[0m[0;34m][0m[0;34m.[0m[0mplot[0m[0;34m([0m[0mt[0m [0;34m/[0m [0;36m3600[0m [0;34m/[0m [0;36m24[0m[0;34m,[0m [0mdata[0m[0;34m[[0m[0;34m'To'[0m[0;34m][0m[0;34m,[0m [0mlabel[0m[0;34m=[0m[0;34m'$Î¸_{outdoor}$'[0m[0;34m)[0m[0;34m[0m[0;34m[0m[0m
[0;32m----> 6[0;31m [0maxs[0m[0;34m[[0m[0;36m0[0m[0;34m][0m[0;34m.[0m[0mplot[0m[0;34m([0m[0mt[0m [0;34m/[0m [0;36m3600[0m [0;34m/[0m [0;36m24[0m[0;34m,[0m [0my_exp[0m[0;34m.[0m[0mval[0m[0;34m,[0m [0mlabel[0m[0;34m=[0m[0;34m'$Î¸_{indoor}$'[0m[0;34m)[0m[0;34m[0m[0;34m[0m[0m
[0m[1;32m      7[0m axs[0].set(ylabel='Temperatures, $Î¸$ / Â°C',
[1;32m      8[0m            title='Simulation for weather')

[0;32m~/opt/anaconda3/lib/python3.9/site-packages/pandas/core/generic.py[0m in [0;36m__getattr__[0;34m(self, name)[0m
[1;32m   5485[0m         ):
[1;32m   5486[0m             [0;32mreturn[0m [0mself[0m[0;34m[[0m[0mname[0m[0;34m][0m[0;34m[0m[0;34m[0m[0m
[0;32m-> 5487[0;31m         [0;32mreturn[0m [0mobject[0m[0;34m.[0m[0m__getattribute__[0m[0;34m([0m[0mself[0m[0;34m,[0m [0mname[0m[0;34m)[0m[0;34m[0m[0;34m[0m[0m
[0m[1;32m   5488[0m [0;34m[0m[0m
[1;32m   5489[0m     [0;32mdef[0m [0m__setattr__[0m[0;34m([0m[0mself[0m[0;34m,[0m [0mname[0m[0;34m:[0m [0mstr[0m[0;34m,[0m [0mvalue[0m[0;34m)[0m [0;34m->[0m [0;32mNone[0m[0;34m:[0m[0;34m[0m[0;34m[0m[0m

[0;31mAttributeError[0m: 'DataFrame' object has no attribute 'val'
AttributeError: 'DataFrame' object has no attribute 'val'

